Workbook

Sheet Cover
B4: Muhammad Zeenat Ullah
B8: CA Finalist (ICAP) · QBO ProAdvisor · Excel Expert
B11: PORTFOLIO PROJECT
B12: Formula Rebuild & Reconstruction HR Payroll Spreadsheet System
B15: Fixed 200+ broken formulas · Built 85 new formulas · System runs 80% faster
B17: CLIENT | D17: DURATION
B18: Summit HR Solutions, Atlanta GA | D18: 4 Days
B20: TOOLS USED | D20: DELIVERABLES
B21: Excel · Advanced Formulas · Dynamic Arrays · SUMIFS · INDEX-MATCH | D21: Fixed Formula Library · New Formulas · Documentation
B23: IMPACT | D23: PAY FREQUENCY
B24: Saved 6 hours/week — Payroll processing now error-free | D24: Bi-Weekly (26 periods/year)
B26: FORMULAS | D26: SCOPE
B27: INDEX-MATCH · Nested IF · SUMIFS · COUNTIF · IFERROR · IRS Pub 15-T W/H | D27: 20 Employees · 5 Departments · Federal + GA Payroll
A31: CONTACT
A32: zeenatullah.bookkeeper@gmail.com · WhatsApp: +44 7577 845321
A33: CA Finalist (ICAP) · QuickBooks Online ProAdvisor · Excel Expert
A34: Portfolio Sample · Client name and all employee data are entirely fictitious · Created to demonstrate formula-building expertise

Sheet Project Summary
A1: PAYROLL FORMULA REBUILD | Summit HR Solutions, Atlanta GA
A2: Prepared by: Muhammad Zeenat Ullah · CA Finalist (ICAP) · QBO ProAdvisor · Excel Expert
B4: 200+ | D4: 85 | F4: 6 hrs | H4: 80%
B5: Broken Formulas Fixed | D5: New Formulas Built | F5: Saved Every Week | H5: Faster Processing
A8: THE SITUATION
B9: WHAT WAS BROKEN | D9: WHAT IT WAS COSTING | G9: WHAT I DELIVERED
B10: Payroll formulas showing errors — numbers could not be trusted | D10: Payroll team manually checking every cell before each run: 6 hours wasted every week | G10: 100% error-free. Every number calculates automatically. Zero manual checking needed.
B11: Federal tax withheld at wrong flat rate — same % for every employee | D11: Employees over/under-withheld. Real risk of IRS underpayment penalties and employee complaints | G11: Correct IRS withholding for every employee based on their salary, filing status, and tax bracket.
B12: Overtime paid at wrong rate — extra pay going out every check | D12: $200–$400 overpaid per overtime employee per pay period. Multiplied across the team = significant loss | G12: Overtime calculated exactly per federal FLSA law. Employees paid correctly — not a dollar more or less.
B13: Salary formulas using wrong pay period divisor | D13: Salaried employees underpaid by approx 8% each check — payroll liability and employee trust issue | G13: All salaries divided correctly for bi-weekly schedule. Every employee paid exact contracted amount.
B14: Year-to-date totals ignoring bonuses and variable pay | D14: W-2 preparation inaccurate. Tax filings at risk. Employees questioning their YTD figures. | G14: True YTD totals pulling from complete payroll history. Accurate for W-2s, audits, and employee records.
B15: Social Security over-deducted for higher earners | D15: High earners over-deducted by up to $847/year. Company exposed to correction and reimbursement costs | G15: SS withholding automatically stops at the IRS annual wage base. Zero over-deduction risk.
B16: Lookup formulas breaking when columns moved | D16: Manual formula repairs needed every pay run — adding to the 6-hour weekly correction burden | G16: Formulas rebuilt so they cannot break from column changes. Works reliably every pay run, permanently.
A18: WHY HIRE ME
B19: CA Finalist (ICAP) | D19: Internationally recognized accounting qualification. I understand payroll not just as formulas, but as financial compliance — taxes, FLSA, IRS rules, and reporting accuracy.
B20: QBO ProAdvisor | D20: Certified in QuickBooks Online. I connect Excel payroll data seamlessly with your accounting software — no double entry, no reconciliation headaches.
B21: Excel Expert | D21: I build spreadsheets that work without you needing to understand a single formula. You enter data. The system does the rest. Permanently.
B22: US Payroll Specific | D22: This workbook uses real IRS Publication 15-T 2024 tables, actual FLSA overtime rules, Georgia state flat tax (5.49%), Social Security wage base ($176,100), and FUTA/SUTA rates. Not generic — built for US compliance.
B23: Portfolio, Not a Template | D23: Every formula in this workbook was written from scratch. Nothing downloaded. Nothing templated. This is original work — which means I can build the same for your specific business needs.
A26: Ready to fix your spreadsheet? — zeenatullah.bookkeeper@gmail.com | WhatsApp: +44 7577 845321 | Muhammad Zeenat Ullah · CA Finalist (ICAP) · QBO ProAdvisor · Excel Expert
A28: Muhammad Zeenat Ullah | CA Finalist (ICAP) | QBO ProAdvisor | Excel Expert | zeenatullah.bookkeeper@gmail.com | WhatsApp: +44 7577 845321
A29: Portfolio Sample — Client name, employee names, and all figures are entirely fictitious. Created to demonstrate advanced Excel payroll formula expertise.

Sheet Before vs After
A1: BEFORE vs AFTER | 10 Real Problems Found and Fixed | Summit HR Solutions
A2: Muhammad Zeenat Ullah · CA Finalist (ICAP) · QBO ProAdvisor · Excel Expert · zeenatullah.bookkeeper@gmail.com
B4: WHAT WAS BROKEN | C4: ERROR IT CAUSED | D4: BUSINESS COST | E4: WHAT I FIXED / BUILT
B5: 1. Employee lookup formulas returning blank results — employee names, rates, and departments not pulling into payroll rows | C5: Payroll rows for affected employees were empty — pay could not be calculated without manual data entry every run | D5: 6+ hours/week of manual data entry. High risk of entry mistakes causing wrong pay amounts | E5: Rebuilt all lookups so they find employee data automatically and reliably — even when the employee list is reorganized or expanded
B6: 2. Federal income tax calculated at a single flat percentage for every employee regardless of salary or filing status | C6: Employees over-withheld or under-withheld on federal tax every single pay period — non-compliant with IRS rules | D6: Risk of IRS underpayment penalties. Employee complaints about wrong take-home pay. Potential back-corrections needed | E6: Federal tax now calculated using official IRS 2024 tables — correct amount for each employee based on their exact salary and filing status
B7: 3. Overtime pay formula multiplying all hours by 1.5x whenever an employee worked overtime | C7: Employees whose regular hours were also multiplied received $200–$400 extra per overtime pay period | D7: Direct payroll overpayment every period overtime occurred. Federal FLSA compliance violation — legal exposure | E7: Overtime recalculated using the FLSA-required method: straight pay for all hours plus a premium only on overtime hours — legally correct
B8: 4. Annual salary divided by 12 (monthly amount) in a bi-weekly payroll system that should divide by 26 | C8: Every salaried employee was underpaid by approximately 8% each pay period | D8: For a $78,000/year employee: $500 underpaid every two weeks. Payroll liability and serious employee trust damage | E8: All salary formulas corrected to bi-weekly division. Every salaried employee now receives exactly their contracted pay each period
B9: 5. Year-to-date totals calculated by multiplying the current pay period amount by the number of periods | C9: YTD figures completely ignored bonuses, overtime variation, and any pay rate changes made during the year | D9: Inaccurate W-2 preparation risk. Employee YTD queries unanswerable. Year-end tax filing exposure | E9: YTD now totals actual payroll history period by period — accurate for every employee regardless of bonuses or variable pay
B10: 6. Social Security deduction applied at 6.2% continuously with no annual wage base limit | C10: High-earning employees kept being deducted Social Security beyond the IRS annual limit of $176,100 | D10: Up to $847 over-deducted per high earner per year. Company required to refund the difference — administrative cost and employee dissatisfaction | E10: Social Security automatically stops deducting the moment an employee reaches the annual wage base. Zero over-deduction possible
B11: 7. Department payroll totals calculated manually or by hardcoded cell ranges that broke when rows changed | C11: Department cost reports were wrong or unavailable — management could not see accurate payroll by department | D11: Management decisions based on incorrect cost data. Budget vs actual comparisons unreliable | E11: Department totals now calculate automatically using the entire payroll data — update instantly when any employee data changes
B12: 8. Georgia state income tax applied to take-home pay after deductions instead of gross wages | C12: State tax under-withheld for every employee — tax base was smaller than it should legally be | D12: Potential Georgia DOR underpayment exposure for all 20 employees across every pay period | E12: Georgia 5.49% flat tax now correctly applied to gross wages — compliant with Georgia Department of Revenue requirements
B13: 9. Benefit deduction formulas returning a blank space instead of zero when an employee had no election | C13: Every total and net pay formula downstream of those cells returned errors — net pay uncalculable | D13: Payroll could not be completed without manually deleting the problematic cells each run — added to the correction burden | E13: All benefit formulas return zero when no deduction applies — net pay and totals calculate cleanly with no manual intervention
B14: 10. Conditional formatting error-highlight rules pointing to a worksheet that had been deleted | C14: Color-coded alerts completely non-functional — payroll errors were invisible until they caused problems | D14: Staff had no early warning system. Errors only discovered after checks were already processed or distributed | E14: Visual alert system fully rebuilt — errors, anomalies, and employees approaching tax limits are all highlighted automatically in color
A15: RESULT: 200+ formulas fixed · 85 new formulas built · 6 hours/week saved · IRS compliant · FLSA compliant · Zero errors remaining
A17: Have a broken spreadsheet? Get in touch: zeenatullah.bookkeeper@gmail.com | WhatsApp: +44 7577 845321
A19: Muhammad Zeenat Ullah | CA Finalist (ICAP) | QBO ProAdvisor | Excel Expert | zeenatullah.bookkeeper@gmail.com | WhatsApp: +44 7577 845321
A20: Portfolio Sample — Client name, employee names, and all figures are entirely fictitious. Created to demonstrate advanced Excel payroll formula expertise.

Sheet Formula Showcase
A1: FORMULA SHOWCASE | Every Formula Built & Fixed | Summit HR Solutions Payroll System
A2: Muhammad Zeenat Ullah · CA Finalist (ICAP) · QBO ProAdvisor · Excel Expert · zeenatullah.bookkeeper@gmail.com · +44 7577 845321
A3: LIVE RESULTS BELOW — Every formula in the Result column is actively pulling real data from the Payroll Register and Employee Master in this workbook. Nothing is hardcoded.
A5: FORMULA USAGE SUMMARY — How Many Times Each Formula Was Used Across This Workbook
B6: FORMULA TYPE | C6: TIMES USED
B7: INDEX-MATCH | C7: 120+ | D7: Lookup formula. Replaces VLOOKUP. Used to pull every employee attribute (name, rate, department, tax rate, benefits) from the Employee Master into the Payroll Register. Works in any direction. Cannot break when columns move.
B8: Nested IF | C8: 20 | D8: Decision formula. Used to calculate federal income tax withholding — checks filing status (MFJ vs Single), then tests 7 tax bracket thresholds in sequence to find the correct IRS percentage. Each employee's withholding calculated precisely per IRS Pub 15-T 2024.
B9: SUMIFS | C9: 48+ | D9: Conditional sum formula. Used in Department Summary to total gross pay, taxes, and deductions per department. Used in YTD Summary to total each employee's year-to-date figures. Updates automatically every pay period.
B10: IFERROR | C10: 100+ | D10: Error-protection formula. Wraps every single lookup formula in the workbook. If an employee ID is not found, returns zero instead of crashing the row with an error. Prevents one bad cell from breaking an entire payroll run.
B11: ROUND | C11: 60+ | D11: Precision formula. Wraps every tax and deduction calculation. Ensures Social Security (6.2%), Medicare (1.45%), and Georgia state tax (5.49%) are always calculated to exactly 2 decimal places — no rounding errors accumulating across 26 pay periods.
B12: COUNTIF | C12: 7 | D12: Counting formula. Used in Department Summary to count employees per department, and in Dashboard to count total active employees. Updates instantly when employee status changes.
B13: SUM | C13: 50+ | D13: Totalling formula. Used in every row to sum gross pay components, tax components, and deduction components. Used in every totals row to sum across all 20 employees. All totals rows use SUM — nothing is manually entered.
B14: IF | C14: 40+ | D14: Logic formula. Used to distinguish salaried vs hourly pay (salary divides annual by 26, hourly multiplies rate by hours), to apply FLSA overtime premium for hourly employees only, and to stop Social Security withholding at the annual wage base.
A16: LIVE DEMONSTRATIONS — Each result below is a real formula pulling live data from this workbook
B17: FORMULA TYPE | C17: LIVE RESULT | D17: FORMULA USED (display) | E17: PLAIN-ENGLISH EXPLANATION
B18: INDEX-MATCH (Employee Lookup) | C18: =IFERROR(INDEX('Employee Master'!B$4:B$23,MATCH("E-1001",'Employee Master'!A$4:A$23,0)),"Not Found") -> Anderson | D18: IFERROR( INDEX( EmployeeName_Range, MATCH( EmpID, EmpID_Range, 0 ) ), "" ) | E18: Finds employee E-1001 in the Employee Master and returns their last name. Uses MATCH to locate the row, INDEX to retrieve the value. IFERROR prevents errors if the ID is missing.
B19: INDEX-MATCH (Salary Lookup) | C19: =IFERROR(INDEX('Employee Master'!I$4:I$23,MATCH("E-1003",'Employee Master'!A$4:A$23,0)),0) -> 125000 | D19: IFERROR( INDEX( AnnualSalary_Range, MATCH( EmpID, EmpID_Range, 0 ) ), 0 ) | E19: Retrieves the annual salary of employee E-1003 (Williams, Controller) from the Employee Master. The same pattern is repeated for every data field: rate, department, filing status, benefits.
B20: INDEX-MATCH (Hourly Rate) | C20: =IFERROR(INDEX('Employee Master'!J$4:J$23,MATCH("E-1009",'Employee Master'!A$4:A$23,0)),0) -> 24.5 | D20: IFERROR( INDEX( HourlyRate_Range, MATCH( EmpID, EmpID_Range, 0 ) ), 0 ) | E20: Retrieves the hourly rate for E-1009 (Wilson, Warehouse Lead) — an hourly employee. The IF formula in gross pay then uses this rate multiplied by hours worked.
B21: IF — Salary vs Hourly (Gross Pay) | C21: =IF(INDEX('Employee Master'!G$4:G$23,MATCH("E-1001",'Employee Master'!A$4:A$23,0))="Salary",INDEX('Employee Master'!I$4:I$23,MATCH("E-1001",'Employee Master'!A$4:A$23,0))/26,INDEX('Employee Master'!J$4:J$23,MATCH("E-1001",'Employee Master'!A$4:A$23,0))*80) -> 4423.0769 | D21: IF( PayType = Salary, AnnualSalary / 26, HourlyRate * RegHours ) | E21: Checks whether the employee is Salaried or Hourly. Salaried employees get annual salary divided by 26 (bi-weekly). Hourly employees get rate multiplied by hours. One formula handles both pay types.
B22: IF — FLSA Overtime (Half-Time Premium) | C22: =IFERROR(INDEX('Employee Master'!J$4:J$23,MATCH("E-1009",'Employee Master'!A$4:A$23,0))*5.5*0.5,0) -> 67.375 | D22: IF( PayType = Hourly, HourlyRate * OT_Hours * 0.5, 0 ) | E22: Calculates the FLSA overtime premium for E-1009 who worked 5.5 OT hours this period. Only the half-time premium (0.5x) is added — the straight-time pay is already included in regular gross. FLSA-compliant.
B23: Nested IF (Federal Withholding MFJ) | C23: =IFERROR(IF((INDEX('Payroll Register'!M$4:M$23,MATCH("E-1001",'Payroll Register'!A$4:A$23,0))*26)<=14600,(INDEX('Payroll Register'!M$4:M$23,MATCH("E-1001",'Payroll Register'!A$4:A$23,0))*26)*0.1,IF((INDEX('Payroll Register'!M$4:M$23,MATCH("E-1001",'Payroll Register'!A$4:A$23,0))*26)<=57750,1460+((INDEX('Payroll Register'!M$4:M$23,MATCH("E-1001",'Payroll Register'!A$4:A$23,0))*26)-14600)*0.12,IF((INDEX('Payroll Register'!M$4:M$23,MATCH("E-1001",'Payroll Register'!A$4:A$23,0))*26)<=113600,6628+((INDEX('Payroll Register'!M$4:M$23,MATCH("E-1001",'Payroll Register'!A$4:A$23,0))*26)-57750)*0.22,18914+((INDEX('Payroll Register'!M$4:M$23,MATCH("E-1001",'Payroll Register'!A$4:A$23,0))*26)-113600)*0.24)))/26,0) -> 740.38462 | D23: IF( Annual<=14600, Annual*10%, IF( Annual<=57750, 1460+(Annual-14600)*12%, IF( Annual<=113600, 6628+(Annual-57750)*22%, 18914+(Annual-113600)*24% ) ) ) / 26 | E23: IRS Pub 15-T 2024 Percentage Method for Married Filing Jointly. Annualizes bi-weekly gross (x26), tests each bracket threshold in sequence, calculates annual tax at correct marginal rate, divides by 26 for per-period withholding. Anderson (E-1001, $115K MFJ) should show ~$740.
B24: Nested IF (Federal Withholding Single) | C24: =IFERROR(IF((INDEX('Payroll Register'!M$4:M$23,MATCH("E-1005",'Payroll Register'!A$4:A$23,0))*26)<=7300,(INDEX('Payroll Register'!M$4:M$23,MATCH("E-1005",'Payroll Register'!A$4:A$23,0))*26)*0.1,IF((INDEX('Payroll Register'!M$4:M$23,MATCH("E-1005",'Payroll Register'!A$4:A$23,0))*26)<=28875,730+((INDEX('Payroll Register'!M$4:M$23,MATCH("E-1005",'Payroll Register'!A$4:A$23,0))*26)-7300)*0.12,IF((INDEX('Payroll Register'!M$4:M$23,MATCH("E-1005",'Payroll Register'!A$4:A$23,0))*26)<=56875,3319+((INDEX('Payroll Register'!M$4:M$23,MATCH("E-1005",'Payroll Register'!A$4:A$23,0))*26)-28875)*0.22,9479+((INDEX('Payroll Register'!M$4:M$23,MATCH("E-1005",'Payroll Register'!A$4:A$23,0))*26)-56875)*0.24)))/26,0) -> 348.71154 | D24: IF( Annual<=7300, Annual*10%, IF( Annual<=28875, 730+(Annual-7300)*12%, IF( Annual<=56875, 3319+(Annual-28875)*22%, 9479+(Annual-56875)*24% ) ) ) / 26 | E24: IRS Pub 15-T 2024 Single filer table. Davis (E-1005, $55K Single) falls in the 22% bracket. Formula annualizes, finds the bracket, calculates tax at correct marginal rate, divides by 26. Should show ~$349.
B25: ROUND — Social Security (6.2% with Wage Base) | C25: =ROUND(IFERROR(INDEX('Payroll Register'!M$4:M$23,MATCH("E-1001",'Payroll Register'!A$4:A$23,0)),0)*0.062,2) -> 274.23 | D25: ROUND( GrossTotal * 0.062, 2 ) | E25: Calculates employee Social Security contribution at 6.2% for Anderson (E-1001). ROUND ensures exactly 2 decimal places — no floating point rounding errors accumulating across 26 pay periods. Full wage base monitor is in YTD Summary.
B26: ROUND — Medicare (1.45% No Wage Base) | C26: =ROUND(IFERROR(INDEX('Payroll Register'!M$4:M$23,MATCH("E-1001",'Payroll Register'!A$4:A$23,0)),0)*0.0145,2) -> 64.13 | D26: ROUND( GrossTotal * 0.0145, 2 ) | E26: Calculates Medicare (HI) tax at 1.45% with no wage base limit. An additional 0.9% applies for wages over $200K annually — monitored in YTD Summary. ROUND prevents cent-level rounding errors.
B27: ROUND — Georgia State Tax (5.49% Flat Rate) | C27: =ROUND(IFERROR(INDEX('Payroll Register'!M$4:M$23,MATCH("E-1001",'Payroll Register'!A$4:A$23,0)),0)*INDEX('Employee Master'!N$4:N$23,MATCH("E-1001",'Employee Master'!A$4:A$23,0)),2) -> 242.83 | D27: ROUND( GrossTotal * INDEX( GA_Rate_Range, MATCH( EmpID, EmpID_Range, 0 ) ), 2 ) | E27: Georgia flat income tax at 5.49% (effective Jan 1 2024) applied to gross wages. Rate is pulled from Employee Master via INDEX-MATCH — if the rate changes, update one cell and the entire payroll updates automatically.
B28: SUMIFS — Department Gross Pay Total | C28: =SUMIFS('Payroll Register'!M$4:M$23,'Payroll Register'!D$4:D$23,"Finance") -> 9692.3077 | D28: SUMIFS( GrossPay_Range, Department_Range, "Finance" ) | E28: Totals gross pay for all Finance department employees in the current pay period. Automatically includes any new Finance employees added to the register. Used across all 6 departments in the Department Summary sheet.
B29: SUMIFS — Department Total Tax Withheld | C29: =SUMIFS('Payroll Register'!R$4:R$23,'Payroll Register'!D$4:D$23,"Information Technology") -> 3571.1877 | D29: SUMIFS( TotalTax_Range, Department_Range, "Information Technology" ) | E29: Totals all tax withheld (federal + SS + Medicare + GA) for the IT department. Management can see total tax burden per department at a glance. Same SUMIFS pattern used for gross, taxes, deductions, and net across all departments.
B30: SUMIFS — YTD (Prior + Current) | C30: =SUMIFS('Prior YTD (Jan-May)'!E$4:E$23,'Prior YTD (Jan-May)'!A$4:A$23,"E-1015")+SUMIFS('Payroll Register'!M$4:M$23,'Payroll Register'!A$4:A$23,"E-1015") -> 69384.612 | D30: SUMIFS( PriorHistory_Gross, EmpID_Range, ThisEmployee ) + SUMIFS( CurrentRegister_Gross, EmpID_Range, ThisEmployee ) | E30: True YTD gross for VP of Sales (E-1015 White) — sums verified prior 10 periods from the Prior YTD sheet plus the current period from the Payroll Register. Includes Q1 and Q2 bonuses already paid. Accurate for W-2 preparation.
B31: SUMIFS — YTD Total Tax Withheld | C31: =SUMIFS('Prior YTD (Jan-May)'!J$4:J$23,'Prior YTD (Jan-May)'!A$4:A$23,"E-1003")+SUMIFS('Payroll Register'!R$4:R$23,'Payroll Register'!A$4:A$23,"E-1003") -> 16108.652 | D31: SUMIFS( PriorTax, EmpID, Employee ) + SUMIFS( CurrentTax, EmpID, Employee ) | E31: Year-to-date total taxes withheld for Williams (E-1003, Controller). Combines prior 10 periods with current period. Accurate cumulative tax figure for year-end reporting and employee tax queries.
B32: COUNTIF — Active Employee Count | C32: =COUNTIF('Employee Master'!K$4:K$23,"Active") -> 20 | D32: COUNTIF( Status_Range, "Active" ) | E32: Counts all employees with Active status in the Employee Master. Used in the Dashboard KPI card. If an employee is terminated (status changed to Inactive), this count automatically decreases and payroll rows are excluded from totals.
B33: COUNTIF — Department Headcount | C33: =COUNTIF('Payroll Register'!D$4:D$23,"Sales") -> 4 | D33: COUNTIF( Department_Range, "Sales" ) | E33: Counts employees in the Sales department for the Department Summary. Management sees headcount alongside payroll cost — enabling cost-per-employee analysis by department. Updates automatically when employees are added or change departments.
B34: IFERROR — Lookup Protection | C34: =IFERROR(INDEX('Employee Master'!B$4:B$23,MATCH("E-9999",'Employee Master'!A$4:A$23,0)),"Employee Not Found") -> Employee Not Found | D34: IFERROR( INDEX( MATCH( ... ) ), "Employee Not Found" ) | E34: Demonstrates error protection — E-9999 does not exist. Without IFERROR this returns a lookup error that cascades into gross pay, taxes, and net pay, breaking the entire row. With IFERROR it returns clean text. Every single lookup in this workbook is wrapped in IFERROR.
B35: IFERROR — Division Protection | C35: =IFERROR(INDEX('Employee Master'!O$4:O$23,MATCH("E-1008",'Employee Master'!A$4:A$23,0))/26,0) -> 11.346154 | D35: IFERROR( BenefitAnnual / 26, 0 ) | E35: Divides E-1008's annual health insurance premium by 26 for the per-period deduction. IFERROR returns 0 if the employee has no benefit election (NULL value) — preventing a division error from crashing the deduction column for that employee.
B36: SUM — Gross Components (Per Employee Row) | C36: =IFERROR(INDEX('Payroll Register'!I$4:I$23,MATCH("E-1015",'Payroll Register'!A$4:A$23,0))+INDEX('Payroll Register'!J$4:J$23,MATCH("E-1015",'Payroll Register'!A$4:A$23,0))+INDEX('Payroll Register'!K$4:K$23,MATCH("E-1015",'Payroll Register'!A$4:A$23,0))+INDEX('Payroll Register'!L$4:L$23,MATCH("E-1015",'Payroll Register'!A$4:A$23,0)),0) -> 7807.6923 | D36: SUM( BasePay, OT_Premium, HolidayPay, Bonus ) | E36: Total gross pay for E-1015 (White, VP Sales) = base salary/26 + overtime premium + holiday pay + bonus/commission. Each component is separate so management can see exactly what drives gross pay. This period includes a $2,500 commission payment.
B37: SUM — Net Pay (Gross minus All Deductions) | C37: =IFERROR(INDEX('Payroll Register'!M$4:M$23,MATCH("E-1001",'Payroll Register'!A$4:A$23,0))-INDEX('Payroll Register'!R$4:R$23,MATCH("E-1001",'Payroll Register'!A$4:A$23,0))-INDEX('Payroll Register'!X$4:X$23,MATCH("E-1001",'Payroll Register'!A$4:A$23,0)),0) -> 2801.1223 | D37: GrossTotal - TotalTaxWithheld - TotalBenefitDeductions | E37: Net take-home pay for Anderson (E-1001, HR Director): gross minus all taxes (federal, SS, Medicare, GA) minus all benefit deductions (health, dental, vision, 401k, life insurance). This is the amount deposited directly to the employee's bank account.
A40: Muhammad Zeenat Ullah | CA Finalist (ICAP) | QBO ProAdvisor | Excel Expert | zeenatullah.bookkeeper@gmail.com | WhatsApp: +44 7577 845321
A41: Portfolio Sample — All company names, employee names, and figures are entirely fictitious. Created to demonstrate advanced Excel payroll formula expertise.

Sheet Dashboard
A1: PAYROLL DASHBOARD | SUMMIT HR SOLUTIONS | Atlanta, GA | Pay Period: June 1–14, 2026
A2: Bi-Weekly · Check Date: June 19, 2026 · 11 Pay Periods YTD · Fed W/H: IRS Pub 15-T Percentage Method · All figures in USD
A4: Total Gross Payroll | D4: Total Net Pay | G4: Total Tax Withheld | J4: Total Deductions | M4: Active Employees
A5: ='Payroll Register'!M24 -> 63678.106 | D5: ='Payroll Register'!Y24 -> 40164.22 | G5: ='Payroll Register'!R24 -> 19263.955 | J5: ='Payroll Register'!X24 -> 4249.9308 | M5: =COUNTIF('Employee Master'!K4:K23,"Active") -> 20
A8: DEPARTMENT BREAKDOWN — CURRENT PAY PERIOD (from Dept Summary via SUMIFS)
A9: Department | B9: Headcount | C9: Gross Pay | D9: Tax W/H | E9: Deductions | F9: Net Pay | G9: % of Gross
A10: Human Resources | B10: ='Dept Summary'!B4 -> 2 | C10: ='Dept Summary'!C4 -> 7423.0769 | D10: ='Dept Summary'!H4 -> 2275.3515 | E10: ='Dept Summary'!I4 -> 444.80308 | F10: ='Dept Summary'!J4 -> 4702.9223 | G10: =C10/'Dept Summary'!C10 -> 0.11657189
A11: Finance | B11: ='Dept Summary'!B5 -> 3 | C11: ='Dept Summary'!C5 -> 9692.3077 | D11: ='Dept Summary'!H5 -> 2959.1462 | E11: ='Dept Summary'!I5 -> 661.54 | F11: ='Dept Summary'!J5 -> 6071.6215 | G11: =C11/'Dept Summary'!C10 -> 0.15220785
A12: Operations | B12: ='Dept Summary'!B6 -> 5 | C12: ='Dept Summary'!C6 -> 11663.221 | D12: ='Dept Summary'!H6 -> 3404.2856 | E12: ='Dept Summary'!I6 -> 604.41923 | F12: ='Dept Summary'!J6 -> 7654.5163 | G12: =C12/'Dept Summary'!C10 -> 0.18315905
A13: Information Technology | B13: ='Dept Summary'!B7 -> 4 | C13: ='Dept Summary'!C7 -> 12088.923 | D13: ='Dept Summary'!H7 -> 3571.1877 | E13: ='Dept Summary'!I7 -> 856.01462 | F13: ='Dept Summary'!J7 -> 7661.7208 | G13: =C13/'Dept Summary'!C10 -> 0.18984426
A14: Sales | B14: ='Dept Summary'!B8 -> 4 | C14: ='Dept Summary'!C8 -> 16425.962 | D14: ='Dept Summary'!H8 -> 5159.9569 | E14: ='Dept Summary'!I8 -> 1211.0369 | F14: ='Dept Summary'!J8 -> 10054.968 | G14: =C14/'Dept Summary'!C10 -> 0.25795305
A15: Marketing | B15: ='Dept Summary'!B9 -> 2 | C15: ='Dept Summary'!C9 -> 6384.6154 | D15: ='Dept Summary'!H9 -> 1894.0269 | E15: ='Dept Summary'!I9 -> 472.11692 | F15: ='Dept Summary'!J9 -> 4018.4715 | G15: =C15/'Dept Summary'!C10 -> 0.1002639
A16: TOTAL | B16: =SUM(B10:B15) -> 20 | C16: =SUM(C10:C15) -> 63678.106 | D16: =SUM(D10:D15) -> 19263.955 | E16: =SUM(E10:E15) -> 4249.9308 | F16: =SUM(F10:F15) -> 40164.22 | G16: =SUM(G10:G15) -> 1
A18: CONFIDENTIAL — Internal Use Only | Summit HR Solutions | Federal W/H per IRS Pub 15-T (2024) — verify brackets for 2026 upon IRS release | Formulas: INDEX-MATCH · SUMIFS · Nested IF · IFERROR · COUNTIF · Dynamic Arrays
A20: Prepared by: Muhammad Zeenat Ullah | CA Finalist (ICAP) · QBO ProAdvisor · Excel Expert | zeenatullah.bookkeeper@gmail.com | WA: +44 7577 845321
A21: Portfolio Sample — All employee names, SSNs, and company data are entirely fictitious and created solely to demonstrate financial formula expertise.

Sheet YTD Summary
A1: YEAR-TO-DATE EARNINGS & TAX SUMMARY | January 1 – June 14, 2026 (11 Pay Periods) | Summit HR Solutions
A2: Formulas used: SUMIFS · INDEX-MATCH · IFERROR · SUM · ROUND · MAX · Nested IF · Division · Arithmetic — Muhammad Zeenat Ullah · CA Finalist (ICAP) · QBO ProAdvisor
A4: SUMIFS | C4: INDEX-MATCH | E4: IFERROR | G4: SUM | I4: ROUND | K4: MAX | M4: Nested IF | O4: Arithmetic
A5: Emp ID | B5: Last Name [INDEX-MATCH] | C5: First Name [INDEX-MATCH] | D5: Department [INDEX-MATCH] | E5: YTD Gross [SUMIFS] | F5: YTD Fed W/H [SUMIFS] | G5: YTD SS Tax [SUMIFS] | H5: YTD Medicare [SUMIFS] | I5: YTD GA Tax [SUMIFS] | J5: YTD Total Tax [SUM] | K5: YTD Health [SUMIFS] | L5: YTD Dental [SUMIFS] | M5: YTD Vision [SUMIFS] | N5: YTD 401(k) [SUMIFS] | O5: YTD Total Ded [SUM] | P5: YTD Net Pay [SUM] | Q5: Eff Tax Rate [ROUND] | R5: 401k % of Gross [ROUND] | S5: SS Base Remaining [MAX] | T5: SS Wage Base Status [Nested IF] | U5: Projected Annual [Arithmetic] | V5: Periods Remaining [Arithmetic]
A6: E-1001 | B6: =IFERROR(INDEX('Employee Master'!B$4:B$23,MATCH(A6,'Employee Master'!A$4:A$23,0)),"") -> Anderson | C6: =IFERROR(INDEX('Employee Master'!C$4:C$23,MATCH(A6,'Employee Master'!A$4:A$23,0)),"") -> Michael | D6: =IFERROR(INDEX('Employee Master'!E$4:E$23,MATCH(A6,'Employee Master'!A$4:A$23,0)),"") -> Human Resources | E6: =SUMIFS('Prior YTD (Jan-May)'!E$4:E$23,'Prior YTD (Jan-May)'!A$4:A$23,A6)+SUMIFS('Payroll Register'!M$4:M$23,'Payroll Register'!A$4:A$23,A6) -> 48653.847 | F6: =SUMIFS('Prior YTD (Jan-May)'!F$4:F$23,'Prior YTD (Jan-May)'!A$4:A$23,A6)+SUMIFS('Payroll Register'!N$4:N$23,'Payroll Register'!A$4:A$23,A6) -> 8144.2346 | G6: =SUMIFS('Prior YTD (Jan-May)'!G$4:G$23,'Prior YTD (Jan-May)'!A$4:A$23,A6)+SUMIFS('Payroll Register'!O$4:O$23,'Payroll Register'!A$4:A$23,A6) -> 3016.54 | H6: =SUMIFS('Prior YTD (Jan-May)'!H$4:H$23,'Prior YTD (Jan-May)'!A$4:A$23,A6)+SUMIFS('Payroll Register'!P$4:P$23,'Payroll Register'!A$4:A$23,A6) -> 705.48 | I6: =SUMIFS('Prior YTD (Jan-May)'!I$4:I$23,'Prior YTD (Jan-May)'!A$4:A$23,A6)+SUMIFS('Payroll Register'!Q$4:Q$23,'Payroll Register'!A$4:A$23,A6) -> 2671.1 | J6: =SUM(F6:I6) -> 14537.355 | K6: =SUMIFS('Prior YTD (Jan-May)'!K$4:K$23,'Prior YTD (Jan-May)'!A$4:A$23,A6)+SUMIFS('Payroll Register'!S$4:S$23,'Payroll Register'!A$4:A$23,A6) -> 359.61231 | L6: =SUMIFS('Prior YTD (Jan-May)'!L$4:L$23,'Prior YTD (Jan-May)'!A$4:A$23,A6)+SUMIFS('Payroll Register'!T$4:T$23,'Payroll Register'!A$4:A$23,A6) -> 19.040769 | M6: =SUMIFS('Prior YTD (Jan-May)'!M$4:M$23,'Prior YTD (Jan-May)'!A$4:A$23,A6)+SUMIFS('Payroll Register'!U$4:U$23,'Payroll Register'!A$4:A$23,A6) -> 6.3469231 | N6: =SUMIFS('Prior YTD (Jan-May)'!N$4:N$23,'Prior YTD (Jan-May)'!A$4:A$23,A6)+SUMIFS('Payroll Register'!V$4:V$23,'Payroll Register'!A$4:A$23,A6) -> 2919.23 | O6: =SUM(K6:N6) -> 3304.23 | P6: =E6-J6-O6 -> 30812.262 | Q6: =IFERROR(ROUND(J6/E6,4),0) -> 0.2988 | R6: =IFERROR(ROUND(N6/E6,4),0) -> 0.06 | S6: =MAX(0,176100-E6) -> 127446.15 | T6: =IF(E6>=176100,"BASE REACHED — STOP SS",IF(E6>=149685,"WARNING: >85% Used",IF(E6>=114465,"MONITOR: >65% Used","Within Safe Limit"))) -> Within Safe Limit | U6: =ROUND(E6/11*26,2) -> 115000 | V6: =26-11 -> 15
A7: E-1002 | B7: =IFERROR(INDEX('Employee Master'!B$4:B$23,MATCH(A7,'Employee Master'!A$4:A$23,0)),"") -> Johnson | C7: =IFERROR(INDEX('Employee Master'!C$4:C$23,MATCH(A7,'Employee Master'!A$4:A$23,0)),"") -> Sarah | D7: =IFERROR(INDEX('Employee Master'!E$4:E$23,MATCH(A7,'Employee Master'!A$4:A$23,0)),"") -> Human Resources | E7: =SUMIFS('Prior YTD (Jan-May)'!E$4:E$23,'Prior YTD (Jan-May)'!A$4:A$23,A7)+SUMIFS('Payroll Register'!M$4:M$23,'Payroll Register'!A$4:A$23,A7) -> 33000 | F7: =SUMIFS('Prior YTD (Jan-May)'!F$4:F$23,'Prior YTD (Jan-May)'!A$4:A$23,A7)+SUMIFS('Payroll Register'!N$4:N$23,'Payroll Register'!A$4:A$23,A7) -> 6155.3469 | G7: =SUMIFS('Prior YTD (Jan-May)'!G$4:G$23,'Prior YTD (Jan-May)'!A$4:A$23,A7)+SUMIFS('Payroll Register'!O$4:O$23,'Payroll Register'!A$4:A$23,A7) -> 2046 | H7: =SUMIFS('Prior YTD (Jan-May)'!H$4:H$23,'Prior YTD (Jan-May)'!A$4:A$23,A7)+SUMIFS('Payroll Register'!P$4:P$23,'Payroll Register'!A$4:A$23,A7) -> 478.5 | I7: =SUMIFS('Prior YTD (Jan-May)'!I$4:I$23,'Prior YTD (Jan-May)'!A$4:A$23,A7)+SUMIFS('Payroll Register'!Q$4:Q$23,'Payroll Register'!A$4:A$23,A7) -> 1811.7 | J7: =SUM(F7:I7) -> 10491.547 | K7: =SUMIFS('Prior YTD (Jan-May)'!K$4:K$23,'Prior YTD (Jan-May)'!A$4:A$23,A7)+SUMIFS('Payroll Register'!S$4:S$23,'Payroll Register'!A$4:A$23,A7) -> 232.69385 | L7: =SUMIFS('Prior YTD (Jan-May)'!L$4:L$23,'Prior YTD (Jan-May)'!A$4:A$23,A7)+SUMIFS('Payroll Register'!T$4:T$23,'Payroll Register'!A$4:A$23,A7) -> 19.040769 | M7: =SUMIFS('Prior YTD (Jan-May)'!M$4:M$23,'Prior YTD (Jan-May)'!A$4:A$23,A7)+SUMIFS('Payroll Register'!U$4:U$23,'Payroll Register'!A$4:A$23,A7) -> 6.3469231 | N7: =SUMIFS('Prior YTD (Jan-May)'!N$4:N$23,'Prior YTD (Jan-May)'!A$4:A$23,A7)+SUMIFS('Payroll Register'!V$4:V$23,'Payroll Register'!A$4:A$23,A7) -> 1320 | O7: =SUM(K7:N7) -> 1578.0815 | P7: =E7-J7-O7 -> 20930.372 | Q7: =IFERROR(ROUND(J7/E7,4),0) -> 0.3179 | R7: =IFERROR(ROUND(N7/E7,4),0) -> 0.04 | S7: =MAX(0,176100-E7) -> 143100 | T7: =IF(E7>=176100,"BASE REACHED — STOP SS",IF(E7>=149685,"WARNING: >85% Used",IF(E7>=114465,"MONITOR: >65% Used","Within Safe Limit"))) -> Within Safe Limit | U7: =ROUND(E7/11*26,2) -> 78000 | V7: =26-11 -> 15
A8: E-1003 | B8: =IFERROR(INDEX('Employee Master'!B$4:B$23,MATCH(A8,'Employee Master'!A$4:A$23,0)),"") -> Williams | C8: =IFERROR(INDEX('Employee Master'!C$4:C$23,MATCH(A8,'Employee Master'!A$4:A$23,0)),"") -> David | D8: =IFERROR(INDEX('Employee Master'!E$4:E$23,MATCH(A8,'Employee Master'!A$4:A$23,0)),"") -> Finance | E8: =SUMIFS('Prior YTD (Jan-May)'!E$4:E$23,'Prior YTD (Jan-May)'!A$4:A$23,A8)+SUMIFS('Payroll Register'!M$4:M$23,'Payroll Register'!A$4:A$23,A8) -> 52884.612 | F8: =SUMIFS('Prior YTD (Jan-May)'!F$4:F$23,'Prior YTD (Jan-May)'!A$4:A$23,A8)+SUMIFS('Payroll Register'!N$4:N$23,'Payroll Register'!A$4:A$23,A8) -> 9159.6123 | G8: =SUMIFS('Prior YTD (Jan-May)'!G$4:G$23,'Prior YTD (Jan-May)'!A$4:A$23,A8)+SUMIFS('Payroll Register'!O$4:O$23,'Payroll Register'!A$4:A$23,A8) -> 3278.85 | H8: =SUMIFS('Prior YTD (Jan-May)'!H$4:H$23,'Prior YTD (Jan-May)'!A$4:A$23,A8)+SUMIFS('Payroll Register'!P$4:P$23,'Payroll Register'!A$4:A$23,A8) -> 766.83 | I8: =SUMIFS('Prior YTD (Jan-May)'!I$4:I$23,'Prior YTD (Jan-May)'!A$4:A$23,A8)+SUMIFS('Payroll Register'!Q$4:Q$23,'Payroll Register'!A$4:A$23,A8) -> 2903.36 | J8: =SUM(F8:I8) -> 16108.652 | K8: =SUMIFS('Prior YTD (Jan-May)'!K$4:K$23,'Prior YTD (Jan-May)'!A$4:A$23,A8)+SUMIFS('Payroll Register'!S$4:S$23,'Payroll Register'!A$4:A$23,A8) -> 359.61231 | L8: =SUMIFS('Prior YTD (Jan-May)'!L$4:L$23,'Prior YTD (Jan-May)'!A$4:A$23,A8)+SUMIFS('Payroll Register'!T$4:T$23,'Payroll Register'!A$4:A$23,A8) -> 19.040769 | M8: =SUMIFS('Prior YTD (Jan-May)'!M$4:M$23,'Prior YTD (Jan-May)'!A$4:A$23,A8)+SUMIFS('Payroll Register'!U$4:U$23,'Payroll Register'!A$4:A$23,A8) -> 6.3469231 | N8: =SUMIFS('Prior YTD (Jan-May)'!N$4:N$23,'Prior YTD (Jan-May)'!A$4:A$23,A8)+SUMIFS('Payroll Register'!V$4:V$23,'Payroll Register'!A$4:A$23,A8) -> 4230.77 | O8: =SUM(K8:N8) -> 4615.77 | P8: =E8-J8-O8 -> 32160.19 | Q8: =IFERROR(ROUND(J8/E8,4),0) -> 0.3046 | R8: =IFERROR(ROUND(N8/E8,4),0) -> 0.08 | S8: =MAX(0,176100-E8) -> 123215.39 | T8: =IF(E8>=176100,"BASE REACHED — STOP SS",IF(E8>=149685,"WARNING: >85% Used",IF(E8>=114465,"MONITOR: >65% Used","Within Safe Limit"))) -> Within Safe Limit | U8: =ROUND(E8/11*26,2) -> 124999.99 | V8: =26-11 -> 15
A9: E-1004 | B9: =IFERROR(INDEX('Employee Master'!B$4:B$23,MATCH(A9,'Employee Master'!A$4:A$23,0)),"") -> Brown | C9: =IFERROR(INDEX('Employee Master'!C$4:C$23,MATCH(A9,'Employee Master'!A$4:A$23,0)),"") -> Jessica | D9: =IFERROR(INDEX('Employee Master'!E$4:E$23,MATCH(A9,'Employee Master'!A$4:A$23,0)),"") -> Finance | E9: =SUMIFS('Prior YTD (Jan-May)'!E$4:E$23,'Prior YTD (Jan-May)'!A$4:A$23,A9)+SUMIFS('Payroll Register'!M$4:M$23,'Payroll Register'!A$4:A$23,A9) -> 30461.541 | F9: =SUMIFS('Prior YTD (Jan-May)'!F$4:F$23,'Prior YTD (Jan-May)'!A$4:A$23,A9)+SUMIFS('Payroll Register'!N$4:N$23,'Payroll Register'!A$4:A$23,A9) -> 5546.1123 | G9: =SUMIFS('Prior YTD (Jan-May)'!G$4:G$23,'Prior YTD (Jan-May)'!A$4:A$23,A9)+SUMIFS('Payroll Register'!O$4:O$23,'Payroll Register'!A$4:A$23,A9) -> 1888.61 | H9: =SUMIFS('Prior YTD (Jan-May)'!H$4:H$23,'Prior YTD (Jan-May)'!A$4:A$23,A9)+SUMIFS('Payroll Register'!P$4:P$23,'Payroll Register'!A$4:A$23,A9) -> 441.69 | I9: =SUMIFS('Prior YTD (Jan-May)'!I$4:I$23,'Prior YTD (Jan-May)'!A$4:A$23,A9)+SUMIFS('Payroll Register'!Q$4:Q$23,'Payroll Register'!A$4:A$23,A9) -> 1672.34 | J9: =SUM(F9:I9) -> 9548.7523 | K9: =SUMIFS('Prior YTD (Jan-May)'!K$4:K$23,'Prior YTD (Jan-May)'!A$4:A$23,A9)+SUMIFS('Payroll Register'!S$4:S$23,'Payroll Register'!A$4:A$23,A9) -> 232.69385 | L9: =SUMIFS('Prior YTD (Jan-May)'!L$4:L$23,'Prior YTD (Jan-May)'!A$4:A$23,A9)+SUMIFS('Payroll Register'!T$4:T$23,'Payroll Register'!A$4:A$23,A9) -> 19.040769 | M9: =SUMIFS('Prior YTD (Jan-May)'!M$4:M$23,'Prior YTD (Jan-May)'!A$4:A$23,A9)+SUMIFS('Payroll Register'!U$4:U$23,'Payroll Register'!A$4:A$23,A9) -> 6.3469231 | N9: =SUMIFS('Prior YTD (Jan-May)'!N$4:N$23,'Prior YTD (Jan-May)'!A$4:A$23,A9)+SUMIFS('Payroll Register'!V$4:V$23,'Payroll Register'!A$4:A$23,A9) -> 1523.08 | O9: =SUM(K9:N9) -> 1781.1615 | P9: =E9-J9-O9 -> 19131.627 | Q9: =IFERROR(ROUND(J9/E9,4),0) -> 0.3135 | R9: =IFERROR(ROUND(N9/E9,4),0) -> 0.05 | S9: =MAX(0,176100-E9) -> 145638.46 | T9: =IF(E9>=176100,"BASE REACHED — STOP SS",IF(E9>=149685,"WARNING: >85% Used",IF(E9>=114465,"MONITOR: >65% Used","Within Safe Limit"))) -> Within Safe Limit | U9: =ROUND(E9/11*26,2) -> 72000.01 | V9: =26-11 -> 15
A10: E-1005 | B10: =IFERROR(INDEX('Employee Master'!B$4:B$23,MATCH(A10,'Employee Master'!A$4:A$23,0)),"") -> Davis | C10: =IFERROR(INDEX('Employee Master'!C$4:C$23,MATCH(A10,'Employee Master'!A$4:A$23,0)),"") -> Robert | D10: =IFERROR(INDEX('Employee Master'!E$4:E$23,MATCH(A10,'Employee Master'!A$4:A$23,0)),"") -> Finance | E10: =SUMIFS('Prior YTD (Jan-May)'!E$4:E$23,'Prior YTD (Jan-May)'!A$4:A$23,A10)+SUMIFS('Payroll Register'!M$4:M$23,'Payroll Register'!A$4:A$23,A10) -> 23269.235 | F10: =SUMIFS('Prior YTD (Jan-May)'!F$4:F$23,'Prior YTD (Jan-May)'!A$4:A$23,A10)+SUMIFS('Payroll Register'!N$4:N$23,'Payroll Register'!A$4:A$23,A10) -> 3835.8315 | G10: =SUMIFS('Prior YTD (Jan-May)'!G$4:G$23,'Prior YTD (Jan-May)'!A$4:A$23,A10)+SUMIFS('Payroll Register'!O$4:O$23,'Payroll Register'!A$4:A$23,A10) -> 1442.69 | H10: =SUMIFS('Prior YTD (Jan-May)'!H$4:H$23,'Prior YTD (Jan-May)'!A$4:A$23,A10)+SUMIFS('Payroll Register'!P$4:P$23,'Payroll Register'!A$4:A$23,A10) -> 337.4 | I10: =SUMIFS('Prior YTD (Jan-May)'!I$4:I$23,'Prior YTD (Jan-May)'!A$4:A$23,A10)+SUMIFS('Payroll Register'!Q$4:Q$23,'Payroll Register'!A$4:A$23,A10) -> 1277.48 | J10: =SUM(F10:I10) -> 6893.4015 | K10: =SUMIFS('Prior YTD (Jan-May)'!K$4:K$23,'Prior YTD (Jan-May)'!A$4:A$23,A10)+SUMIFS('Payroll Register'!S$4:S$23,'Payroll Register'!A$4:A$23,A10) -> 124.80615 | L10: =SUMIFS('Prior YTD (Jan-May)'!L$4:L$23,'Prior YTD (Jan-May)'!A$4:A$23,A10)+SUMIFS('Payroll Register'!T$4:T$23,'Payroll Register'!A$4:A$23,A10) -> 19.040769 | M10: =SUMIFS('Prior YTD (Jan-May)'!M$4:M$23,'Prior YTD (Jan-May)'!A$4:A$23,A10)+SUMIFS('Payroll Register'!U$4:U$23,'Payroll Register'!A$4:A$23,A10) -> 6.3469231 | N10: =SUMIFS('Prior YTD (Jan-May)'!N$4:N$23,'Prior YTD (Jan-May)'!A$4:A$23,A10)+SUMIFS('Payroll Register'!V$4:V$23,'Payroll Register'!A$4:A$23,A10) -> 698.08 | O10: =SUM(K10:N10) -> 848.27385 | P10: =E10-J10-O10 -> 15527.559 | Q10: =IFERROR(ROUND(J10/E10,4),0) -> 0.2962 | R10: =IFERROR(ROUND(N10/E10,4),0) -> 0.03 | S10: =MAX(0,176100-E10) -> 152830.77 | T10: =IF(E10>=176100,"BASE REACHED — STOP SS",IF(E10>=149685,"WARNING: >85% Used",IF(E10>=114465,"MONITOR: >65% Used","Within Safe Limit"))) -> Within Safe Limit | U10: =ROUND(E10/11*26,2) -> 55000.01 | V10: =26-11 -> 15
A11: E-1006 | B11: =IFERROR(INDEX('Employee Master'!B$4:B$23,MATCH(A11,'Employee Master'!A$4:A$23,0)),"") -> Martinez | C11: =IFERROR(INDEX('Employee Master'!C$4:C$23,MATCH(A11,'Employee Master'!A$4:A$23,0)),"") -> Elena | D11: =IFERROR(INDEX('Employee Master'!E$4:E$23,MATCH(A11,'Employee Master'!A$4:A$23,0)),"") -> Operations | E11: =SUMIFS('Prior YTD (Jan-May)'!E$4:E$23,'Prior YTD (Jan-May)'!A$4:A$23,A11)+SUMIFS('Payroll Register'!M$4:M$23,'Payroll Register'!A$4:A$23,A11) -> 40192.306 | F11: =SUMIFS('Prior YTD (Jan-May)'!F$4:F$23,'Prior YTD (Jan-May)'!A$4:A$23,A11)+SUMIFS('Payroll Register'!N$4:N$23,'Payroll Register'!A$4:A$23,A11) -> 6271.2654 | G11: =SUMIFS('Prior YTD (Jan-May)'!G$4:G$23,'Prior YTD (Jan-May)'!A$4:A$23,A11)+SUMIFS('Payroll Register'!O$4:O$23,'Payroll Register'!A$4:A$23,A11) -> 2491.92 | H11: =SUMIFS('Prior YTD (Jan-May)'!H$4:H$23,'Prior YTD (Jan-May)'!A$4:A$23,A11)+SUMIFS('Payroll Register'!P$4:P$23,'Payroll Register'!A$4:A$23,A11) -> 582.79 | I11: =SUMIFS('Prior YTD (Jan-May)'!I$4:I$23,'Prior YTD (Jan-May)'!A$4:A$23,A11)+SUMIFS('Payroll Register'!Q$4:Q$23,'Payroll Register'!A$4:A$23,A11) -> 2206.56 | J11: =SUM(F11:I11) -> 11552.535 | K11: =SUMIFS('Prior YTD (Jan-May)'!K$4:K$23,'Prior YTD (Jan-May)'!A$4:A$23,A11)+SUMIFS('Payroll Register'!S$4:S$23,'Payroll Register'!A$4:A$23,A11) -> 359.61231 | L11: =SUMIFS('Prior YTD (Jan-May)'!L$4:L$23,'Prior YTD (Jan-May)'!A$4:A$23,A11)+SUMIFS('Payroll Register'!T$4:T$23,'Payroll Register'!A$4:A$23,A11) -> 19.040769 | M11: =SUMIFS('Prior YTD (Jan-May)'!M$4:M$23,'Prior YTD (Jan-May)'!A$4:A$23,A11)+SUMIFS('Payroll Register'!U$4:U$23,'Payroll Register'!A$4:A$23,A11) -> 6.3469231 | N11: =SUMIFS('Prior YTD (Jan-May)'!N$4:N$23,'Prior YTD (Jan-May)'!A$4:A$23,A11)+SUMIFS('Payroll Register'!V$4:V$23,'Payroll Register'!A$4:A$23,A11) -> 2813.46 | O11: =SUM(K11:N11) -> 3198.46 | P11: =E11-J11-O11 -> 25441.311 | Q11: =IFERROR(ROUND(J11/E11,4),0) -> 0.2874 | R11: =IFERROR(ROUND(N11/E11,4),0) -> 0.07 | S11: =MAX(0,176100-E11) -> 135907.69 | T11: =IF(E11>=176100,"BASE REACHED — STOP SS",IF(E11>=149685,"WARNING: >85% Used",IF(E11>=114465,"MONITOR: >65% Used","Within Safe Limit"))) -> Within Safe Limit | U11: =ROUND(E11/11*26,2) -> 95000 | V11: =26-11 -> 15
A12: E-1007 | B12: =IFERROR(INDEX('Employee Master'!B$4:B$23,MATCH(A12,'Employee Master'!A$4:A$23,0)),"") -> Garcia | C12: =IFERROR(INDEX('Employee Master'!C$4:C$23,MATCH(A12,'Employee Master'!A$4:A$23,0)),"") -> Carlos | D12: =IFERROR(INDEX('Employee Master'!E$4:E$23,MATCH(A12,'Employee Master'!A$4:A$23,0)),"") -> Operations | E12: =SUMIFS('Prior YTD (Jan-May)'!E$4:E$23,'Prior YTD (Jan-May)'!A$4:A$23,A12)+SUMIFS('Payroll Register'!M$4:M$23,'Payroll Register'!A$4:A$23,A12) -> 27500 | F12: =SUMIFS('Prior YTD (Jan-May)'!F$4:F$23,'Prior YTD (Jan-May)'!A$4:A$23,A12)+SUMIFS('Payroll Register'!N$4:N$23,'Payroll Register'!A$4:A$23,A12) -> 4835.3469 | G12: =SUMIFS('Prior YTD (Jan-May)'!G$4:G$23,'Prior YTD (Jan-May)'!A$4:A$23,A12)+SUMIFS('Payroll Register'!O$4:O$23,'Payroll Register'!A$4:A$23,A12) -> 1705 | H12: =SUMIFS('Prior YTD (Jan-May)'!H$4:H$23,'Prior YTD (Jan-May)'!A$4:A$23,A12)+SUMIFS('Payroll Register'!P$4:P$23,'Payroll Register'!A$4:A$23,A12) -> 398.75 | I12: =SUMIFS('Prior YTD (Jan-May)'!I$4:I$23,'Prior YTD (Jan-May)'!A$4:A$23,A12)+SUMIFS('Payroll Register'!Q$4:Q$23,'Payroll Register'!A$4:A$23,A12) -> 1509.75 | J12: =SUM(F12:I12) -> 8448.8469 | K12: =SUMIFS('Prior YTD (Jan-May)'!K$4:K$23,'Prior YTD (Jan-May)'!A$4:A$23,A12)+SUMIFS('Payroll Register'!S$4:S$23,'Payroll Register'!A$4:A$23,A12) -> 262.30615 | L12: =SUMIFS('Prior YTD (Jan-May)'!L$4:L$23,'Prior YTD (Jan-May)'!A$4:A$23,A12)+SUMIFS('Payroll Register'!T$4:T$23,'Payroll Register'!A$4:A$23,A12) -> 19.040769 | M12: =SUMIFS('Prior YTD (Jan-May)'!M$4:M$23,'Prior YTD (Jan-May)'!A$4:A$23,A12)+SUMIFS('Payroll Register'!U$4:U$23,'Payroll Register'!A$4:A$23,A12) -> 6.3469231 | N12: =SUMIFS('Prior YTD (Jan-May)'!N$4:N$23,'Prior YTD (Jan-May)'!A$4:A$23,A12)+SUMIFS('Payroll Register'!V$4:V$23,'Payroll Register'!A$4:A$23,A12) -> 1375 | O12: =SUM(K12:N12) -> 1662.6938 | P12: =E12-J12-O12 -> 17388.459 | Q12: =IFERROR(ROUND(J12/E12,4),0) -> 0.3072 | R12: =IFERROR(ROUND(N12/E12,4),0) -> 0.05 | S12: =MAX(0,176100-E12) -> 148600 | T12: =IF(E12>=176100,"BASE REACHED — STOP SS",IF(E12>=149685,"WARNING: >85% Used",IF(E12>=114465,"MONITOR: >65% Used","Within Safe Limit"))) -> Within Safe Limit | U12: =ROUND(E12/11*26,2) -> 65000 | V12: =26-11 -> 15
A13: E-1008 | B13: =IFERROR(INDEX('Employee Master'!B$4:B$23,MATCH(A13,'Employee Master'!A$4:A$23,0)),"") -> Miller | C13: =IFERROR(INDEX('Employee Master'!C$4:C$23,MATCH(A13,'Employee Master'!A$4:A$23,0)),"") -> Amanda | D13: =IFERROR(INDEX('Employee Master'!E$4:E$23,MATCH(A13,'Employee Master'!A$4:A$23,0)),"") -> Operations | E13: =SUMIFS('Prior YTD (Jan-May)'!E$4:E$23,'Prior YTD (Jan-May)'!A$4:A$23,A13)+SUMIFS('Payroll Register'!M$4:M$23,'Payroll Register'!A$4:A$23,A13) -> 22000 | F13: =SUMIFS('Prior YTD (Jan-May)'!F$4:F$23,'Prior YTD (Jan-May)'!A$4:A$23,A13)+SUMIFS('Payroll Register'!N$4:N$23,'Payroll Register'!A$4:A$23,A13) -> 3556.5969 | G13: =SUMIFS('Prior YTD (Jan-May)'!G$4:G$23,'Prior YTD (Jan-May)'!A$4:A$23,A13)+SUMIFS('Payroll Register'!O$4:O$23,'Payroll Register'!A$4:A$23,A13) -> 1364 | H13: =SUMIFS('Prior YTD (Jan-May)'!H$4:H$23,'Prior YTD (Jan-May)'!A$4:A$23,A13)+SUMIFS('Payroll Register'!P$4:P$23,'Payroll Register'!A$4:A$23,A13) -> 319 | I13: =SUMIFS('Prior YTD (Jan-May)'!I$4:I$23,'Prior YTD (Jan-May)'!A$4:A$23,A13)+SUMIFS('Payroll Register'!Q$4:Q$23,'Payroll Register'!A$4:A$23,A13) -> 1207.8 | J13: =SUM(F13:I13) -> 6447.3969 | K13: =SUMIFS('Prior YTD (Jan-May)'!K$4:K$23,'Prior YTD (Jan-May)'!A$4:A$23,A13)+SUMIFS('Payroll Register'!S$4:S$23,'Payroll Register'!A$4:A$23,A13) -> 124.80615 | L13: =SUMIFS('Prior YTD (Jan-May)'!L$4:L$23,'Prior YTD (Jan-May)'!A$4:A$23,A13)+SUMIFS('Payroll Register'!T$4:T$23,'Payroll Register'!A$4:A$23,A13) -> 19.040769 | M13: =SUMIFS('Prior YTD (Jan-May)'!M$4:M$23,'Prior YTD (Jan-May)'!A$4:A$23,A13)+SUMIFS('Payroll Register'!U$4:U$23,'Payroll Register'!A$4:A$23,A13) -> 0 | N13: =SUMIFS('Prior YTD (Jan-May)'!N$4:N$23,'Prior YTD (Jan-May)'!A$4:A$23,A13)+SUMIFS('Payroll Register'!V$4:V$23,'Payroll Register'!A$4:A$23,A13) -> 660 | O13: =SUM(K13:N13) -> 803.84692 | P13: =E13-J13-O13 -> 14748.756 | Q13: =IFERROR(ROUND(J13/E13,4),0) -> 0.2931 | R13: =IFERROR(ROUND(N13/E13,4),0) -> 0.03 | S13: =MAX(0,176100-E13) -> 154100 | T13: =IF(E13>=176100,"BASE REACHED — STOP SS",IF(E13>=149685,"WARNING: >85% Used",IF(E13>=114465,"MONITOR: >65% Used","Within Safe Limit"))) -> Within Safe Limit | U13: =ROUND(E13/11*26,2) -> 52000 | V13: =26-11 -> 15
A14: E-1009 | B14: =IFERROR(INDEX('Employee Master'!B$4:B$23,MATCH(A14,'Employee Master'!A$4:A$23,0)),"") -> Wilson | C14: =IFERROR(INDEX('Employee Master'!C$4:C$23,MATCH(A14,'Employee Master'!A$4:A$23,0)),"") -> James | D14: =IFERROR(INDEX('Employee Master'!E$4:E$23,MATCH(A14,'Employee Master'!A$4:A$23,0)),"") -> Operations | E14: =SUMIFS('Prior YTD (Jan-May)'!E$4:E$23,'Prior YTD (Jan-May)'!A$4:A$23,A14)+SUMIFS('Payroll Register'!M$4:M$23,'Payroll Register'!A$4:A$23,A14) -> 23023.875 | F14: =SUMIFS('Prior YTD (Jan-May)'!F$4:F$23,'Prior YTD (Jan-May)'!A$4:A$23,A14)+SUMIFS('Payroll Register'!N$4:N$23,'Payroll Register'!A$4:A$23,A14) -> 3781.8494 | G14: =SUMIFS('Prior YTD (Jan-May)'!G$4:G$23,'Prior YTD (Jan-May)'!A$4:A$23,A14)+SUMIFS('Payroll Register'!O$4:O$23,'Payroll Register'!A$4:A$23,A14) -> 1427.48 | H14: =SUMIFS('Prior YTD (Jan-May)'!H$4:H$23,'Prior YTD (Jan-May)'!A$4:A$23,A14)+SUMIFS('Payroll Register'!P$4:P$23,'Payroll Register'!A$4:A$23,A14) -> 333.85 | I14: =SUMIFS('Prior YTD (Jan-May)'!I$4:I$23,'Prior YTD (Jan-May)'!A$4:A$23,A14)+SUMIFS('Payroll Register'!Q$4:Q$23,'Payroll Register'!A$4:A$23,A14) -> 1264.01 | J14: =SUM(F14:I14) -> 6807.1894 | K14: =SUMIFS('Prior YTD (Jan-May)'!K$4:K$23,'Prior YTD (Jan-May)'!A$4:A$23,A14)+SUMIFS('Payroll Register'!S$4:S$23,'Payroll Register'!A$4:A$23,A14) -> 124.80615 | L14: =SUMIFS('Prior YTD (Jan-May)'!L$4:L$23,'Prior YTD (Jan-May)'!A$4:A$23,A14)+SUMIFS('Payroll Register'!T$4:T$23,'Payroll Register'!A$4:A$23,A14) -> 19.040769 | M14: =SUMIFS('Prior YTD (Jan-May)'!M$4:M$23,'Prior YTD (Jan-May)'!A$4:A$23,A14)+SUMIFS('Payroll Register'!U$4:U$23,'Payroll Register'!A$4:A$23,A14) -> 6.3469231 | N14: =SUMIFS('Prior YTD (Jan-May)'!N$4:N$23,'Prior YTD (Jan-May)'!A$4:A$23,A14)+SUMIFS('Payroll Register'!V$4:V$23,'Payroll Register'!A$4:A$23,A14) -> 690.71 | O14: =SUM(K14:N14) -> 840.90385 | P14: =E14-J14-O14 -> 15375.782 | Q14: =IFERROR(ROUND(J14/E14,4),0) -> 0.2957 | R14: =IFERROR(ROUND(N14/E14,4),0) -> 0.03 | S14: =MAX(0,176100-E14) -> 153076.12 | T14: =IF(E14>=176100,"BASE REACHED — STOP SS",IF(E14>=149685,"WARNING: >85% Used",IF(E14>=114465,"MONITOR: >65% Used","Within Safe Limit"))) -> Within Safe Limit | U14: =ROUND(E14/11*26,2) -> 54420.07 | V14: =26-11 -> 15
A15: E-1010 | B15: =IFERROR(INDEX('Employee Master'!B$4:B$23,MATCH(A15,'Employee Master'!A$4:A$23,0)),"") -> Moore | C15: =IFERROR(INDEX('Employee Master'!C$4:C$23,MATCH(A15,'Employee Master'!A$4:A$23,0)),"") -> Patricia | D15: =IFERROR(INDEX('Employee Master'!E$4:E$23,MATCH(A15,'Employee Master'!A$4:A$23,0)),"") -> Operations | E15: =SUMIFS('Prior YTD (Jan-May)'!E$4:E$23,'Prior YTD (Jan-May)'!A$4:A$23,A15)+SUMIFS('Payroll Register'!M$4:M$23,'Payroll Register'!A$4:A$23,A15) -> 17281.25 | F15: =SUMIFS('Prior YTD (Jan-May)'!F$4:F$23,'Prior YTD (Jan-May)'!A$4:A$23,A15)+SUMIFS('Payroll Register'!N$4:N$23,'Payroll Register'!A$4:A$23,A15) -> 2518.4669 | G15: =SUMIFS('Prior YTD (Jan-May)'!G$4:G$23,'Prior YTD (Jan-May)'!A$4:A$23,A15)+SUMIFS('Payroll Register'!O$4:O$23,'Payroll Register'!A$4:A$23,A15) -> 1071.44 | H15: =SUMIFS('Prior YTD (Jan-May)'!H$4:H$23,'Prior YTD (Jan-May)'!A$4:A$23,A15)+SUMIFS('Payroll Register'!P$4:P$23,'Payroll Register'!A$4:A$23,A15) -> 250.58 | I15: =SUMIFS('Prior YTD (Jan-May)'!I$4:I$23,'Prior YTD (Jan-May)'!A$4:A$23,A15)+SUMIFS('Payroll Register'!Q$4:Q$23,'Payroll Register'!A$4:A$23,A15) -> 948.74 | J15: =SUM(F15:I15) -> 4789.2269 | K15: =SUMIFS('Prior YTD (Jan-May)'!K$4:K$23,'Prior YTD (Jan-May)'!A$4:A$23,A15)+SUMIFS('Payroll Register'!S$4:S$23,'Payroll Register'!A$4:A$23,A15) -> 124.80615 | L15: =SUMIFS('Prior YTD (Jan-May)'!L$4:L$23,'Prior YTD (Jan-May)'!A$4:A$23,A15)+SUMIFS('Payroll Register'!T$4:T$23,'Payroll Register'!A$4:A$23,A15) -> 19.040769 | M15: =SUMIFS('Prior YTD (Jan-May)'!M$4:M$23,'Prior YTD (Jan-May)'!A$4:A$23,A15)+SUMIFS('Payroll Register'!U$4:U$23,'Payroll Register'!A$4:A$23,A15) -> 0 | N15: =SUMIFS('Prior YTD (Jan-May)'!N$4:N$23,'Prior YTD (Jan-May)'!A$4:A$23,A15)+SUMIFS('Payroll Register'!V$4:V$23,'Payroll Register'!A$4:A$23,A15) -> 0 | O15: =SUM(K15:N15) -> 143.84692 | P15: =E15-J15-O15 -> 12348.176 | Q15: =IFERROR(ROUND(J15/E15,4),0) -> 0.2771 | R15: =IFERROR(ROUND(N15/E15,4),0) -> 0 | S15: =MAX(0,176100-E15) -> 158818.75 | T15: =IF(E15>=176100,"BASE REACHED — STOP SS",IF(E15>=149685,"WARNING: >85% Used",IF(E15>=114465,"MONITOR: >65% Used","Within Safe Limit"))) -> Within Safe Limit | U15: =ROUND(E15/11*26,2) -> 40846.59 | V15: =26-11 -> 15
A16: E-1011 | B16: =IFERROR(INDEX('Employee Master'!B$4:B$23,MATCH(A16,'Employee Master'!A$4:A$23,0)),"") -> Taylor | C16: =IFERROR(INDEX('Employee Master'!C$4:C$23,MATCH(A16,'Employee Master'!A$4:A$23,0)),"") -> Kevin | D16: =IFERROR(INDEX('Employee Master'!E$4:E$23,MATCH(A16,'Employee Master'!A$4:A$23,0)),"") -> Information Technology | E16: =SUMIFS('Prior YTD (Jan-May)'!E$4:E$23,'Prior YTD (Jan-May)'!A$4:A$23,A16)+SUMIFS('Payroll Register'!M$4:M$23,'Payroll Register'!A$4:A$23,A16) -> 44423.072 | F16: =SUMIFS('Prior YTD (Jan-May)'!F$4:F$23,'Prior YTD (Jan-May)'!A$4:A$23,A16)+SUMIFS('Payroll Register'!N$4:N$23,'Payroll Register'!A$4:A$23,A16) -> 7202.0408 | G16: =SUMIFS('Prior YTD (Jan-May)'!G$4:G$23,'Prior YTD (Jan-May)'!A$4:A$23,A16)+SUMIFS('Payroll Register'!O$4:O$23,'Payroll Register'!A$4:A$23,A16) -> 2754.23 | H16: =SUMIFS('Prior YTD (Jan-May)'!H$4:H$23,'Prior YTD (Jan-May)'!A$4:A$23,A16)+SUMIFS('Payroll Register'!P$4:P$23,'Payroll Register'!A$4:A$23,A16) -> 644.14 | I16: =SUMIFS('Prior YTD (Jan-May)'!I$4:I$23,'Prior YTD (Jan-May)'!A$4:A$23,A16)+SUMIFS('Payroll Register'!Q$4:Q$23,'Payroll Register'!A$4:A$23,A16) -> 2438.83 | J16: =SUM(F16:I16) -> 13039.241 | K16: =SUMIFS('Prior YTD (Jan-May)'!K$4:K$23,'Prior YTD (Jan-May)'!A$4:A$23,A16)+SUMIFS('Payroll Register'!S$4:S$23,'Payroll Register'!A$4:A$23,A16) -> 359.61231 | L16: =SUMIFS('Prior YTD (Jan-May)'!L$4:L$23,'Prior YTD (Jan-May)'!A$4:A$23,A16)+SUMIFS('Payroll Register'!T$4:T$23,'Payroll Register'!A$4:A$23,A16) -> 19.040769 | M16: =SUMIFS('Prior YTD (Jan-May)'!M$4:M$23,'Prior YTD (Jan-May)'!A$4:A$23,A16)+SUMIFS('Payroll Register'!U$4:U$23,'Payroll Register'!A$4:A$23,A16) -> 6.3469231 | N16: =SUMIFS('Prior YTD (Jan-May)'!N$4:N$23,'Prior YTD (Jan-May)'!A$4:A$23,A16)+SUMIFS('Payroll Register'!V$4:V$23,'Payroll Register'!A$4:A$23,A16) -> 3553.85 | O16: =SUM(K16:N16) -> 3938.85 | P16: =E16-J16-O16 -> 27444.981 | Q16: =IFERROR(ROUND(J16/E16,4),0) -> 0.2935 | R16: =IFERROR(ROUND(N16/E16,4),0) -> 0.08 | S16: =MAX(0,176100-E16) -> 131676.93 | T16: =IF(E16>=176100,"BASE REACHED — STOP SS",IF(E16>=149685,"WARNING: >85% Used",IF(E16>=114465,"MONITOR: >65% Used","Within Safe Limit"))) -> Within Safe Limit | U16: =ROUND(E16/11*26,2) -> 104999.99 | V16: =26-11 -> 15
A17: E-1012 | B17: =IFERROR(INDEX('Employee Master'!B$4:B$23,MATCH(A17,'Employee Master'!A$4:A$23,0)),"") -> Anderson | C17: =IFERROR(INDEX('Employee Master'!C$4:C$23,MATCH(A17,'Employee Master'!A$4:A$23,0)),"") -> Lisa | D17: =IFERROR(INDEX('Employee Master'!E$4:E$23,MATCH(A17,'Employee Master'!A$4:A$23,0)),"") -> Information Technology | E17: =SUMIFS('Prior YTD (Jan-May)'!E$4:E$23,'Prior YTD (Jan-May)'!A$4:A$23,A17)+SUMIFS('Payroll Register'!M$4:M$23,'Payroll Register'!A$4:A$23,A17) -> 34692.306 | F17: =SUMIFS('Prior YTD (Jan-May)'!F$4:F$23,'Prior YTD (Jan-May)'!A$4:A$23,A17)+SUMIFS('Payroll Register'!N$4:N$23,'Payroll Register'!A$4:A$23,A17) -> 5061.2654 | G17: =SUMIFS('Prior YTD (Jan-May)'!G$4:G$23,'Prior YTD (Jan-May)'!A$4:A$23,A17)+SUMIFS('Payroll Register'!O$4:O$23,'Payroll Register'!A$4:A$23,A17) -> 2150.92 | H17: =SUMIFS('Prior YTD (Jan-May)'!H$4:H$23,'Prior YTD (Jan-May)'!A$4:A$23,A17)+SUMIFS('Payroll Register'!P$4:P$23,'Payroll Register'!A$4:A$23,A17) -> 503.04 | I17: =SUMIFS('Prior YTD (Jan-May)'!I$4:I$23,'Prior YTD (Jan-May)'!A$4:A$23,A17)+SUMIFS('Payroll Register'!Q$4:Q$23,'Payroll Register'!A$4:A$23,A17) -> 1904.61 | J17: =SUM(F17:I17) -> 9619.8354 | K17: =SUMIFS('Prior YTD (Jan-May)'!K$4:K$23,'Prior YTD (Jan-May)'!A$4:A$23,A17)+SUMIFS('Payroll Register'!S$4:S$23,'Payroll Register'!A$4:A$23,A17) -> 359.61231 | L17: =SUMIFS('Prior YTD (Jan-May)'!L$4:L$23,'Prior YTD (Jan-May)'!A$4:A$23,A17)+SUMIFS('Payroll Register'!T$4:T$23,'Payroll Register'!A$4:A$23,A17) -> 19.040769 | M17: =SUMIFS('Prior YTD (Jan-May)'!M$4:M$23,'Prior YTD (Jan-May)'!A$4:A$23,A17)+SUMIFS('Payroll Register'!U$4:U$23,'Payroll Register'!A$4:A$23,A17) -> 6.3469231 | N17: =SUMIFS('Prior YTD (Jan-May)'!N$4:N$23,'Prior YTD (Jan-May)'!A$4:A$23,A17)+SUMIFS('Payroll Register'!V$4:V$23,'Payroll Register'!A$4:A$23,A17) -> 2081.54 | O17: =SUM(K17:N17) -> 2466.54 | P17: =E17-J17-O17 -> 22605.931 | Q17: =IFERROR(ROUND(J17/E17,4),0) -> 0.2773 | R17: =IFERROR(ROUND(N17/E17,4),0) -> 0.06 | S17: =MAX(0,176100-E17) -> 141407.69 | T17: =IF(E17>=176100,"BASE REACHED — STOP SS",IF(E17>=149685,"WARNING: >85% Used",IF(E17>=114465,"MONITOR: >65% Used","Within Safe Limit"))) -> Within Safe Limit | U17: =ROUND(E17/11*26,2) -> 82000 | V17: =26-11 -> 15
... A25: E-1020 | B25: =IFERROR(INDEX('Employee Master'!B$4:B$23,MATCH(A25,'Employee Master'!A$4:A$23,0)),"") -> Martinez | C25: =IFERROR(INDEX('Employee Master'!C$4:C$23,MATCH(A25,'Employee Master'!A$4:A$23,0)),"") -> Sofia | D25: =IFERROR(INDEX('Employee Master'!E$4:E$23,MATCH(A25,'Employee Master'!A$4:A$23,0)),"") -> Marketing | E25: =SUMIFS('Prior YTD (Jan-May)'!E$4:E$23,'Prior YTD (Jan-May)'!A$4:A$23,A25)+SUMIFS('Payroll Register'!M$4:M$23,'Payroll Register'!A$4:A$23,A25) -> 24538.459 | F25: =SUMIFS('Prior YTD (Jan-May)'!F$4:F$23,'Prior YTD (Jan-May)'!A$4:A$23,A25)+SUMIFS('Payroll Register'!N$4:N$23,'Payroll Register'!A$4:A$23,A25) -> 4124.5715 | G25: =SUMIFS('Prior YTD (Jan-May)'!G$4:G$23,'Prior YTD (Jan-May)'!A$4:A$23,A25)+SUMIFS('Payroll Register'!O$4:O$23,'Payroll Register'!A$4:A$23,A25) -> 1521.39 | H25: =SUMIFS('Prior YTD (Jan-May)'!H$4:H$23,'Prior YTD (Jan-May)'!A$4:A$23,A25)+SUMIFS('Payroll Register'!P$4:P$23,'Payroll Register'!A$4:A$23,A25) -> 355.81 | I25: =SUMIFS('Prior YTD (Jan-May)'!I$4:I$23,'Prior YTD (Jan-May)'!A$4:A$23,A25)+SUMIFS('Payroll Register'!Q$4:Q$23,'Payroll Register'!A$4:A$23,A25) -> 1347.16 | J25: =SUM(F25:I25) -> 7348.9315 | K25: =SUMIFS('Prior YTD (Jan-May)'!K$4:K$23,'Prior YTD (Jan-May)'!A$4:A$23,A25)+SUMIFS('Payroll Register'!S$4:S$23,'Payroll Register'!A$4:A$23,A25) -> 124.80615 | L25: =SUMIFS('Prior YTD (Jan-May)'!L$4:L$23,'Prior YTD (Jan-May)'!A$4:A$23,A25)+SUMIFS('Payroll Register'!T$4:T$23,'Payroll Register'!A$4:A$23,A25) -> 19.040769 | M25: =SUMIFS('Prior YTD (Jan-May)'!M$4:M$23,'Prior YTD (Jan-May)'!A$4:A$23,A25)+SUMIFS('Payroll Register'!U$4:U$23,'Payroll Register'!A$4:A$23,A25) -> 6.3469231 | N25: =SUMIFS('Prior YTD (Jan-May)'!N$4:N$23,'Prior YTD (Jan-May)'!A$4:A$23,A25)+SUMIFS('Payroll Register'!V$4:V$23,'Payroll Register'!A$4:A$23,A25) -> 981.54 | O25: =SUM(K25:N25) -> 1131.7338 | P25: =E25-J25-O25 -> 16057.794 | Q25: =IFERROR(ROUND(J25/E25,4),0) -> 0.2995 | R25: =IFERROR(ROUND(N25/E25,4),0) -> 0.04 | S25: =MAX(0,176100-E25) -> 151561.54 | T25: =IF(E25>=176100,"BASE REACHED — STOP SS",IF(E25>=149685,"WARNING: >85% Used",IF(E25>=114465,"MONITOR: >65% Used","Within Safe Limit"))) -> Within Safe Limit | U25: =ROUND(E25/11*26,2) -> 57999.99 | V25: =26-11 -> 15
A26: COMPANY TOTALS — YTD JAN 1 TO JUN 14, 2026 | E26: =SUM(E6:E25) -> 672533.15 | F26: =SUM(F6:F25) -> 113275.36 | G26: =SUM(G6:G25) -> 41697.07 | H26: =SUM(H6:H25) -> 9751.75 | I26: =SUM(I6:I25) -> 36922.07 | J26: =SUM(J6:J25) -> 201646.25 | K26: =SUM(K6:K25) -> 4835.7354 | L26: =SUM(L6:L25) -> 380.81538 | ... P26: =SUM(P6:P25) -> 426561.61 | Q26: =IFERROR(ROUND(AVERAGE(Q6:Q25),4),0) -> 0.2969 | R26: =IFERROR(ROUND(AVERAGE(R6:R25),4),0) -> 0.0485 | S26: =MAX(0,3522000-SUM(E6:E25)) -> 2849466.9 | U26: =SUM(U6:U25) -> 1589623.8 | V26: =26-11 -> 15
A28: FORMULA KEY — Every formula type used in this sheet and what it does
B29: INDEX-MATCH | D29: Columns B, C, D | E29: Pulls employee Last Name, First Name, and Department from Employee Master by matching Emp ID. Works even if the Employee Master columns are rearranged. Wrapped in IFERROR so missing IDs return blank instead of an error.
B30: SUMIFS | D30: Columns E–I, K–N | E30: Sums each payroll figure (gross, federal tax, SS, Medicare, GA tax, health, dental, vision, 401k) by matching Employee ID across both the Prior YTD sheet (10 periods) and the current Payroll Register. This is the core of accurate YTD — real history, not a multiplication.
B31: SUM | D31: Columns J, O, P | E31: Column J: sums Federal + SS + Medicare + GA tax to give total tax withheld. Column O: sums all four benefit deductions. Column P: Gross minus Total Tax minus Total Deductions = Net Pay. These aggregate the SUMIFS results into summary figures.
B32: ROUND | D32: Columns Q, R | E32: Column Q: ROUND(Total Tax / Gross, 4) = effective tax rate as a percentage. Column R: ROUND(YTD 401k / Gross, 4) = actual 401k contribution rate. ROUND ensures clean percentages — prevents 15.999999% displaying instead of 16.00%.
B33: MAX | D33: Column S | E33: MAX(0, 176100 - YTD Gross) = how much Social Security wage capacity each employee has remaining. MAX(0, ...) ensures the result never goes negative for employees who have already crossed the base. Critical for payroll compliance — SS withholding must stop at $176,100.
B34: Nested IF | D34: Column T | E34: Three-level IF checks YTD Gross against SS wage base thresholds: IF >= $176,100 → BASE REACHED — STOP SS (red highlight), IF >= $149,685 (85%) → WARNING: monitor closely (orange), IF >= $114,465 (65%) → MONITOR: approaching. Gives payroll staff an automated early-warning system for SS compliance.
